2020-07-17 15:19:42,609 ERROR: Exception on /user/bharat [GET] [in c:\users\lenovo\desktop\microblog\python-projects\microblog\venv\lib\site-packages\flask\app.py:1892]
Traceback (most recent call last):
  File "c:\users\lenovo\desktop\microblog\python-projects\microblog\venv\lib\site-packages\flask\app.py", line 2447, in wsgi_app
    response = self.full_dispatch_request()
  File "c:\users\lenovo\desktop\microblog\python-projects\microblog\venv\lib\site-packages\flask\app.py", line 1952, in full_dispatch_request
    rv = self.handle_user_exception(e)
  File "c:\users\lenovo\desktop\microblog\python-projects\microblog\venv\lib\site-packages\flask\app.py", line 1821, in handle_user_exception
    reraise(exc_type, exc_value, tb)
  File "c:\users\lenovo\desktop\microblog\python-projects\microblog\venv\lib\site-packages\flask\_compat.py", line 39, in reraise
    raise value
  File "c:\users\lenovo\desktop\microblog\python-projects\microblog\venv\lib\site-packages\flask\app.py", line 1950, in full_dispatch_request
    rv = self.dispatch_request()
  File "c:\users\lenovo\desktop\microblog\python-projects\microblog\venv\lib\site-packages\flask\app.py", line 1936, in dispatch_request
    return self.view_functions[rule.endpoint](**req.view_args)
  File "c:\users\lenovo\desktop\microblog\python-projects\microblog\venv\lib\site-packages\flask_login\utils.py", line 272, in decorated_view
    return func(*args, **kwargs)
  File "C:\Users\lenovo\Desktop\microblog\Python-Projects\Microblog\app\routes.py", line 79, in user
    return render_template('user.html',user = user,posts=posts,form=form)
  File "c:\users\lenovo\desktop\microblog\python-projects\microblog\venv\lib\site-packages\flask\templating.py", line 140, in render_template
    ctx.app,
  File "c:\users\lenovo\desktop\microblog\python-projects\microblog\venv\lib\site-packages\flask\templating.py", line 120, in _render
    rv = template.render(context)
  File "c:\users\lenovo\desktop\microblog\python-projects\microblog\venv\lib\site-packages\jinja2\environment.py", line 1090, in render
    self.environment.handle_exception()
  File "c:\users\lenovo\desktop\microblog\python-projects\microblog\venv\lib\site-packages\jinja2\environment.py", line 832, in handle_exception
    reraise(*rewrite_traceback_stack(source=source))
  File "c:\users\lenovo\desktop\microblog\python-projects\microblog\venv\lib\site-packages\jinja2\_compat.py", line 28, in reraise
    raise value.with_traceback(tb)
  File "C:\Users\lenovo\Desktop\microblog\Python-Projects\Microblog\app\templates\user.html", line 1, in top-level template code
    {% extends "base.html" %}
  File "C:\Users\lenovo\Desktop\microblog\Python-Projects\Microblog\app\templates\base.html", line 29, in top-level template code
    {% block content %}{% endblock %}
  File "C:\Users\lenovo\Desktop\microblog\Python-Projects\Microblog\app\templates\user.html", line 17, in block "content"
    {{form.submit(value='Follow')}}
jinja2.exceptions.UndefinedError: 'app.forms.EmptyForm object' has no attribute 'submit'
2020-07-17 15:19:57,326 INFO: Microblog startup [in C:\Users\lenovo\Desktop\microblog\Python-Projects\Microblog\app\__init__.py:44]
